Traceback (most recent call last):
  File "C:\Users\Miguel\AppData\Local\Programs\Python\Python310\lib\site-packages\jupyter_cache\executors\utils.py", line 58, in single_nb_execution
    executenb(
  File "C:\Users\Miguel\AppData\Local\Programs\Python\Python310\lib\site-packages\nbclient\client.py", line 1314, in execute
    return NotebookClient(nb=nb, resources=resources, km=km, **kwargs).execute()
  File "C:\Users\Miguel\AppData\Local\Programs\Python\Python310\lib\site-packages\jupyter_core\utils\__init__.py", line 165, in wrapped
    return loop.run_until_complete(inner)
  File "C:\Users\Miguel\AppData\Local\Programs\Python\Python310\lib\asyncio\base_events.py", line 646, in run_until_complete
    return future.result()
  File "C:\Users\Miguel\AppData\Local\Programs\Python\Python310\lib\site-packages\nbclient\client.py", line 709, in async_execute
    await self.async_execute_cell(
  File "C:\Users\Miguel\AppData\Local\Programs\Python\Python310\lib\site-packages\nbclient\client.py", line 1062, in async_execute_cell
    await self._check_raise_for_error(cell, cell_index, exec_reply)
  File "C:\Users\Miguel\AppData\Local\Programs\Python\Python310\lib\site-packages\nbclient\client.py", line 918, in _check_raise_for_error
    raise CellExecutionError.from_cell_and_msg(cell, exec_reply_content)
nbclient.exceptions.CellExecutionError: An error occurred while executing the following cell:
------------------
import json
import requests

query = """
query IntrospectionQuery {
  __schema {
	queryType { name }
	mutationType { name }
	subscriptionType { name }
	types {
	  ...FullType
	}
	directives {
	  name
	  description
	  locations
	  args {
		...InputValue
	  }
	}
  }
}

fragment FullType on __Type {
  kind
  name
  description
  fields(includeDeprecated: true) {
	name
	description
	args {
	  ...InputValue
	}
	type {
	  ...TypeRef
	}
	isDeprecated
	deprecationReason
  }
  inputFields {
	...InputValue
  }
  interfaces {
	...TypeRef
  }
  enumValues(includeDeprecated: true) {
	name
	description
	isDeprecated
	deprecationReason
  }
  possibleTypes {
	...TypeRef
  }
}

fragment InputValue on __InputValue {
  name
  description
  type { ...TypeRef }
  defaultValue
}

fragment TypeRef on __Type {
  kind
  name
  ofType {
	kind
	name
	ofType {
	  kind
	  name
	  ofType {
		kind
		name
		ofType {
		  kind
		  name
		  ofType {
			kind
			name
			ofType {
			  kind
			  name
			  ofType {
				kind
				name
			  }
			}
		  }
		}
	  }
	}
  }
}
"""
json_data = {
    'query': query,
}
response = requests.post('http://0.0.0.0:8000/graphql', json=json_data)
print(json.dumps(response.json(), indent=2))
------------------


[1;31m---------------------------------------------------------------------------[0m
[1;31mOSError[0m                                   Traceback (most recent call last)
File [1;32m~\AppData\Local\Programs\Python\Python310\lib\site-packages\urllib3\connection.py:174[0m, in [0;36mHTTPConnection._new_conn[1;34m(self)[0m
[0;32m    173[0m [38;5;28;01mtry[39;00m:
[1;32m--> 174[0m     conn [38;5;241m=[39m connection[38;5;241m.[39mcreate_connection(
[0;32m    175[0m         ([38;5;28mself[39m[38;5;241m.[39m_dns_host, [38;5;28mself[39m[38;5;241m.[39mport), [38;5;28mself[39m[38;5;241m.[39mtimeout, [38;5;241m*[39m[38;5;241m*[39mextra_kw
[0;32m    176[0m     )
[0;32m    178[0m [38;5;28;01mexcept[39;00m SocketTimeout:

File [1;32m~\AppData\Local\Programs\Python\Python310\lib\site-packages\urllib3\util\connection.py:95[0m, in [0;36mcreate_connection[1;34m(address, timeout, source_address, socket_options)[0m
[0;32m     94[0m [38;5;28;01mif[39;00m err [38;5;129;01mis[39;00m [38;5;129;01mnot[39;00m [38;5;28;01mNone[39;00m:
[1;32m---> 95[0m     [38;5;28;01mraise[39;00m err
[0;32m     97[0m [38;5;28;01mraise[39;00m socket[38;5;241m.[39merror([38;5;124m"[39m[38;5;124mgetaddrinfo returns an empty list[39m[38;5;124m"[39m)

File [1;32m~\AppData\Local\Programs\Python\Python310\lib\site-packages\urllib3\util\connection.py:85[0m, in [0;36mcreate_connection[1;34m(address, timeout, source_address, socket_options)[0m
[0;32m     84[0m     sock[38;5;241m.[39mbind(source_address)
[1;32m---> 85[0m [43msock[49m[38;5;241;43m.[39;49m[43mconnect[49m[43m([49m[43msa[49m[43m)[49m
[0;32m     86[0m [38;5;28;01mreturn[39;00m sock

[1;31mOSError[0m: [WinError 10049] The requested address is not valid in its context

During handling of the above exception, another exception occurred:

[1;31mNewConnectionError[0m                        Traceback (most recent call last)
File [1;32m~\AppData\Local\Programs\Python\Python310\lib\site-packages\urllib3\connectionpool.py:715[0m, in [0;36mHTTPConnectionPool.urlopen[1;34m(self, method, url, body, headers, retries, redirect, assert_same_host, timeout, pool_timeout, release_conn, chunked, body_pos, **response_kw)[0m
[0;32m    714[0m [38;5;66;03m# Make the request on the httplib connection object.[39;00m
[1;32m--> 715[0m httplib_response [38;5;241m=[39m [38;5;28;43mself[39;49m[38;5;241;43m.[39;49m[43m_make_request[49m[43m([49m
[0;32m    716[0m [43m    [49m[43mconn[49m[43m,[49m
[0;32m    717[0m [43m    [49m[43mmethod[49m[43m,[49m
[0;32m    718[0m [43m    [49m[43murl[49m[43m,[49m
[0;32m    719[0m [43m    [49m[43mtimeout[49m[38;5;241;43m=[39;49m[43mtimeout_obj[49m[43m,[49m
[0;32m    720[0m [43m    [49m[43mbody[49m[38;5;241;43m=[39;49m[43mbody[49m[43m,[49m
[0;32m    721[0m [43m    [49m[43mheaders[49m[38;5;241;43m=[39;49m[43mheaders[49m[43m,[49m
[0;32m    722[0m [43m    [49m[43mchunked[49m[38;5;241;43m=[39;49m[43mchunked[49m[43m,[49m
[0;32m    723[0m [43m[49m[43m)[49m
[0;32m    725[0m [38;5;66;03m# If we're going to release the connection in ``finally:``, then[39;00m
[0;32m    726[0m [38;5;66;03m# the response doesn't need to know about the connection. Otherwise[39;00m
[0;32m    727[0m [38;5;66;03m# it will also try to release it and we'll have a double-release[39;00m
[0;32m    728[0m [38;5;66;03m# mess.[39;00m

File [1;32m~\AppData\Local\Programs\Python\Python310\lib\site-packages\urllib3\connectionpool.py:416[0m, in [0;36mHTTPConnectionPool._make_request[1;34m(self, conn, method, url, timeout, chunked, **httplib_request_kw)[0m
[0;32m    415[0m     [38;5;28;01melse[39;00m:
[1;32m--> 416[0m         conn[38;5;241m.[39mrequest(method, url, [38;5;241m*[39m[38;5;241m*[39mhttplib_request_kw)
[0;32m    418[0m [38;5;66;03m# We are swallowing BrokenPipeError (errno.EPIPE) since the server is[39;00m
[0;32m    419[0m [38;5;66;03m# legitimately able to close the connection after sending a valid response.[39;00m
[0;32m    420[0m [38;5;66;03m# With this behaviour, the received response is still readable.[39;00m

File [1;32m~\AppData\Local\Programs\Python\Python310\lib\site-packages\urllib3\connection.py:244[0m, in [0;36mHTTPConnection.request[1;34m(self, method, url, body, headers)[0m
[0;32m    243[0m     headers[[38;5;124m"[39m[38;5;124mUser-Agent[39m[38;5;124m"[39m] [38;5;241m=[39m _get_default_user_agent()
[1;32m--> 244[0m [38;5;28;43msuper[39;49m[43m([49m[43mHTTPConnection[49m[43m,[49m[43m [49m[38;5;28;43mself[39;49m[43m)[49m[38;5;241;43m.[39;49m[43mrequest[49m[43m([49m[43mmethod[49m[43m,[49m[43m [49m[43murl[49m[43m,[49m[43m [49m[43mbody[49m[38;5;241;43m=[39;49m[43mbody[49m[43m,[49m[43m [49m[43mheaders[49m[38;5;241;43m=[39;49m[43mheaders[49m[43m)[49m

File [1;32m~\AppData\Local\Programs\Python\Python310\lib\http\client.py:1282[0m, in [0;36mHTTPConnection.request[1;34m(self, method, url, body, headers, encode_chunked)[0m
[0;32m   1281[0m [38;5;250m[39m[38;5;124;03m"""Send a complete request to the server."""[39;00m
[1;32m-> 1282[0m [38;5;28;43mself[39;49m[38;5;241;43m.[39;49m[43m_send_request[49m[43m([49m[43mmethod[49m[43m,[49m[43m [49m[43murl[49m[43m,[49m[43m [49m[43mbody[49m[43m,[49m[43m [49m[43mheaders[49m[43m,[49m[43m [49m[43mencode_chunked[49m[43m)[49m

File [1;32m~\AppData\Local\Programs\Python\Python310\lib\http\client.py:1328[0m, in [0;36mHTTPConnection._send_request[1;34m(self, method, url, body, headers, encode_chunked)[0m
[0;32m   1327[0m     body [38;5;241m=[39m _encode(body, [38;5;124m'[39m[38;5;124mbody[39m[38;5;124m'[39m)
[1;32m-> 1328[0m [38;5;28;43mself[39;49m[38;5;241;43m.[39;49m[43mendheaders[49m[43m([49m[43mbody[49m[43m,[49m[43m [49m[43mencode_chunked[49m[38;5;241;43m=[39;49m[43mencode_chunked[49m[43m)[49m

File [1;32m~\AppData\Local\Programs\Python\Python310\lib\http\client.py:1277[0m, in [0;36mHTTPConnection.endheaders[1;34m(self, message_body, encode_chunked)[0m
[0;32m   1276[0m     [38;5;28;01mraise[39;00m CannotSendHeader()
[1;32m-> 1277[0m [38;5;28;43mself[39;49m[38;5;241;43m.[39;49m[43m_send_output[49m[43m([49m[43mmessage_body[49m[43m,[49m[43m [49m[43mencode_chunked[49m[38;5;241;43m=[39;49m[43mencode_chunked[49m[43m)[49m

File [1;32m~\AppData\Local\Programs\Python\Python310\lib\http\client.py:1037[0m, in [0;36mHTTPConnection._send_output[1;34m(self, message_body, encode_chunked)[0m
[0;32m   1036[0m [38;5;28;01mdel[39;00m [38;5;28mself[39m[38;5;241m.[39m_buffer[:]
[1;32m-> 1037[0m [38;5;28;43mself[39;49m[38;5;241;43m.[39;49m[43msend[49m[43m([49m[43mmsg[49m[43m)[49m
[0;32m   1039[0m [38;5;28;01mif[39;00m message_body [38;5;129;01mis[39;00m [38;5;129;01mnot[39;00m [38;5;28;01mNone[39;00m:
[0;32m   1040[0m 
[0;32m   1041[0m     [38;5;66;03m# create a consistent interface to message_body[39;00m

File [1;32m~\AppData\Local\Programs\Python\Python310\lib\http\client.py:975[0m, in [0;36mHTTPConnection.send[1;34m(self, data)[0m
[0;32m    974[0m [38;5;28;01mif[39;00m [38;5;28mself[39m[38;5;241m.[39mauto_open:
[1;32m--> 975[0m     [38;5;28;43mself[39;49m[38;5;241;43m.[39;49m[43mconnect[49m[43m([49m[43m)[49m
[0;32m    976[0m [38;5;28;01melse[39;00m:

File [1;32m~\AppData\Local\Programs\Python\Python310\lib\site-packages\urllib3\connection.py:205[0m, in [0;36mHTTPConnection.connect[1;34m(self)[0m
[0;32m    204[0m [38;5;28;01mdef[39;00m [38;5;21mconnect[39m([38;5;28mself[39m):
[1;32m--> 205[0m     conn [38;5;241m=[39m [38;5;28;43mself[39;49m[38;5;241;43m.[39;49m[43m_new_conn[49m[43m([49m[43m)[49m
[0;32m    206[0m     [38;5;28mself[39m[38;5;241m.[39m_prepare_conn(conn)

File [1;32m~\AppData\Local\Programs\Python\Python310\lib\site-packages\urllib3\connection.py:186[0m, in [0;36mHTTPConnection._new_conn[1;34m(self)[0m
[0;32m    185[0m [38;5;28;01mexcept[39;00m SocketError [38;5;28;01mas[39;00m e:
[1;32m--> 186[0m     [38;5;28;01mraise[39;00m NewConnectionError(
[0;32m    187[0m         [38;5;28mself[39m, [38;5;124m"[39m[38;5;124mFailed to establish a new connection: [39m[38;5;132;01m%s[39;00m[38;5;124m"[39m [38;5;241m%[39m e
[0;32m    188[0m     )
[0;32m    190[0m [38;5;28;01mreturn[39;00m conn

[1;31mNewConnectionError[0m: <urllib3.connection.HTTPConnection object at 0x0000021E9671A350>: Failed to establish a new connection: [WinError 10049] The requested address is not valid in its context

During handling of the above exception, another exception occurred:

[1;31mMaxRetryError[0m                             Traceback (most recent call last)
File [1;32m~\AppData\Local\Programs\Python\Python310\lib\site-packages\requests\adapters.py:486[0m, in [0;36mHTTPAdapter.send[1;34m(self, request, stream, timeout, verify, cert, proxies)[0m
[0;32m    485[0m [38;5;28;01mtry[39;00m:
[1;32m--> 486[0m     resp [38;5;241m=[39m [43mconn[49m[38;5;241;43m.[39;49m[43murlopen[49m[43m([49m
[0;32m    487[0m [43m        [49m[43mmethod[49m[38;5;241;43m=[39;49m[43mrequest[49m[38;5;241;43m.[39;49m[43mmethod[49m[43m,[49m
[0;32m    488[0m [43m        [49m[43murl[49m[38;5;241;43m=[39;49m[43murl[49m[43m,[49m
[0;32m    489[0m [43m        [49m[43mbody[49m[38;5;241;43m=[39;49m[43mrequest[49m[38;5;241;43m.[39;49m[43mbody[49m[43m,[49m
[0;32m    490[0m [43m        [49m[43mheaders[49m[38;5;241;43m=[39;49m[43mrequest[49m[38;5;241;43m.[39;49m[43mheaders[49m[43m,[49m
[0;32m    491[0m [43m        [49m[43mredirect[49m[38;5;241;43m=[39;49m[38;5;28;43;01mFalse[39;49;00m[43m,[49m
[0;32m    492[0m [43m        [49m[43massert_same_host[49m[38;5;241;43m=[39;49m[38;5;28;43;01mFalse[39;49;00m[43m,[49m
[0;32m    493[0m [43m        [49m[43mpreload_content[49m[38;5;241;43m=[39;49m[38;5;28;43;01mFalse[39;49;00m[43m,[49m
[0;32m    494[0m [43m        [49m[43mdecode_content[49m[38;5;241;43m=[39;49m[38;5;28;43;01mFalse[39;49;00m[43m,[49m
[0;32m    495[0m [43m        [49m[43mretries[49m[38;5;241;43m=[39;49m[38;5;28;43mself[39;49m[38;5;241;43m.[39;49m[43mmax_retries[49m[43m,[49m
[0;32m    496[0m [43m        [49m[43mtimeout[49m[38;5;241;43m=[39;49m[43mtimeout[49m[43m,[49m
[0;32m    497[0m [43m        [49m[43mchunked[49m[38;5;241;43m=[39;49m[43mchunked[49m[43m,[49m
[0;32m    498[0m [43m    [49m[43m)[49m
[0;32m    500[0m [38;5;28;01mexcept[39;00m (ProtocolError, [38;5;167;01mOSError[39;00m) [38;5;28;01mas[39;00m err:

File [1;32m~\AppData\Local\Programs\Python\Python310\lib\site-packages\urllib3\connectionpool.py:799[0m, in [0;36mHTTPConnectionPool.urlopen[1;34m(self, method, url, body, headers, retries, redirect, assert_same_host, timeout, pool_timeout, release_conn, chunked, body_pos, **response_kw)[0m
[0;32m    797[0m     e [38;5;241m=[39m ProtocolError([38;5;124m"[39m[38;5;124mConnection aborted.[39m[38;5;124m"[39m, e)
[1;32m--> 799[0m retries [38;5;241m=[39m [43mretries[49m[38;5;241;43m.[39;49m[43mincrement[49m[43m([49m
[0;32m    800[0m [43m    [49m[43mmethod[49m[43m,[49m[43m [49m[43murl[49m[43m,[49m[43m [49m[43merror[49m[38;5;241;43m=[39;49m[43me[49m[43m,[49m[43m [49m[43m_pool[49m[38;5;241;43m=[39;49m[38;5;28;43mself[39;49m[43m,[49m[43m [49m[43m_stacktrace[49m[38;5;241;43m=[39;49m[43msys[49m[38;5;241;43m.[39;49m[43mexc_info[49m[43m([49m[43m)[49m[43m[[49m[38;5;241;43m2[39;49m[43m][49m
[0;32m    801[0m [43m[49m[43m)[49m
[0;32m    802[0m retries[38;5;241m.[39msleep()

File [1;32m~\AppData\Local\Programs\Python\Python310\lib\site-packages\urllib3\util\retry.py:592[0m, in [0;36mRetry.increment[1;34m(self, method, url, response, error, _pool, _stacktrace)[0m
[0;32m    591[0m [38;5;28;01mif[39;00m new_retry[38;5;241m.[39mis_exhausted():
[1;32m--> 592[0m     [38;5;28;01mraise[39;00m MaxRetryError(_pool, url, error [38;5;129;01mor[39;00m ResponseError(cause))
[0;32m    594[0m log[38;5;241m.[39mdebug([38;5;124m"[39m[38;5;124mIncremented Retry for (url=[39m[38;5;124m'[39m[38;5;132;01m%s[39;00m[38;5;124m'[39m[38;5;124m): [39m[38;5;132;01m%r[39;00m[38;5;124m"[39m, url, new_retry)

[1;31mMaxRetryError[0m: HTTPConnectionPool(host='0.0.0.0', port=8000): Max retries exceeded with url: /graphql (Caused by NewConnectionError('<urllib3.connection.HTTPConnection object at 0x0000021E9671A350>: Failed to establish a new connection: [WinError 10049] The requested address is not valid in its context'))

During handling of the above exception, another exception occurred:

[1;31mConnectionError[0m                           Traceback (most recent call last)
Cell [1;32mIn[1], line 100[0m
[0;32m      4[0m query [38;5;241m=[39m [38;5;124m"""[39m
[0;32m      5[0m [38;5;124mquery IntrospectionQuery [39m[38;5;124m{[39m
[0;32m      6[0m [38;5;124m  __schema [39m[38;5;124m{[39m
[1;32m   (...)[0m
[0;32m     95[0m [38;5;124m}[39m
[0;32m     96[0m [38;5;124m"""[39m
[0;32m     97[0m json_data [38;5;241m=[39m {
[0;32m     98[0m     [38;5;124m'[39m[38;5;124mquery[39m[38;5;124m'[39m: query,
[0;32m     99[0m }
[1;32m--> 100[0m response [38;5;241m=[39m [43mrequests[49m[38;5;241;43m.[39;49m[43mpost[49m[43m([49m[38;5;124;43m'[39;49m[38;5;124;43mhttp://0.0.0.0:8000/graphql[39;49m[38;5;124;43m'[39;49m[43m,[49m[43m [49m[43mjson[49m[38;5;241;43m=[39;49m[43mjson_data[49m[43m)[49m
[0;32m    101[0m [38;5;28mprint[39m(json[38;5;241m.[39mdumps(response[38;5;241m.[39mjson(), indent[38;5;241m=[39m[38;5;241m2[39m))

File [1;32m~\AppData\Local\Programs\Python\Python310\lib\site-packages\requests\api.py:115[0m, in [0;36mpost[1;34m(url, data, json, **kwargs)[0m
[0;32m    103[0m [38;5;28;01mdef[39;00m [38;5;21mpost[39m(url, data[38;5;241m=[39m[38;5;28;01mNone[39;00m, json[38;5;241m=[39m[38;5;28;01mNone[39;00m, [38;5;241m*[39m[38;5;241m*[39mkwargs):
[0;32m    104[0m [38;5;250m    [39m[38;5;124mr[39m[38;5;124;03m"""Sends a POST request.[39;00m
[0;32m    105[0m 
[0;32m    106[0m [38;5;124;03m    :param url: URL for the new :class:`Request` object.[39;00m
[1;32m   (...)[0m
[0;32m    112[0m [38;5;124;03m    :rtype: requests.Response[39;00m
[0;32m    113[0m [38;5;124;03m    """[39;00m
[1;32m--> 115[0m     [38;5;28;01mreturn[39;00m request([38;5;124m"[39m[38;5;124mpost[39m[38;5;124m"[39m, url, data[38;5;241m=[39mdata, json[38;5;241m=[39mjson, [38;5;241m*[39m[38;5;241m*[39mkwargs)

File [1;32m~\AppData\Local\Programs\Python\Python310\lib\site-packages\requests\api.py:59[0m, in [0;36mrequest[1;34m(method, url, **kwargs)[0m
[0;32m     55[0m [38;5;66;03m# By using the 'with' statement we are sure the session is closed, thus we[39;00m
[0;32m     56[0m [38;5;66;03m# avoid leaving sockets open which can trigger a ResourceWarning in some[39;00m
[0;32m     57[0m [38;5;66;03m# cases, and look like a memory leak in others.[39;00m
[0;32m     58[0m [38;5;28;01mwith[39;00m sessions[38;5;241m.[39mSession() [38;5;28;01mas[39;00m session:
[1;32m---> 59[0m     [38;5;28;01mreturn[39;00m session[38;5;241m.[39mrequest(method[38;5;241m=[39mmethod, url[38;5;241m=[39murl, [38;5;241m*[39m[38;5;241m*[39mkwargs)

File [1;32m~\AppData\Local\Programs\Python\Python310\lib\site-packages\requests\sessions.py:589[0m, in [0;36mSession.request[1;34m(self, method, url, params, data, headers, cookies, files, auth, timeout, allow_redirects, proxies, hooks, stream, verify, cert, json)[0m
[0;32m    584[0m send_kwargs [38;5;241m=[39m {
[0;32m    585[0m     [38;5;124m"[39m[38;5;124mtimeout[39m[38;5;124m"[39m: timeout,
[0;32m    586[0m     [38;5;124m"[39m[38;5;124mallow_redirects[39m[38;5;124m"[39m: allow_redirects,
[0;32m    587[0m }
[0;32m    588[0m send_kwargs[38;5;241m.[39mupdate(settings)
[1;32m--> 589[0m resp [38;5;241m=[39m [38;5;28mself[39m[38;5;241m.[39msend(prep, [38;5;241m*[39m[38;5;241m*[39msend_kwargs)
[0;32m    591[0m [38;5;28;01mreturn[39;00m resp

File [1;32m~\AppData\Local\Programs\Python\Python310\lib\site-packages\requests\sessions.py:703[0m, in [0;36mSession.send[1;34m(self, request, **kwargs)[0m
[0;32m    700[0m start [38;5;241m=[39m preferred_clock()
[0;32m    702[0m [38;5;66;03m# Send the request[39;00m
[1;32m--> 703[0m r [38;5;241m=[39m adapter[38;5;241m.[39msend(request, [38;5;241m*[39m[38;5;241m*[39mkwargs)
[0;32m    705[0m [38;5;66;03m# Total elapsed time of the request (approximately)[39;00m
[0;32m    706[0m elapsed [38;5;241m=[39m preferred_clock() [38;5;241m-[39m start

File [1;32m~\AppData\Local\Programs\Python\Python310\lib\site-packages\requests\adapters.py:519[0m, in [0;36mHTTPAdapter.send[1;34m(self, request, stream, timeout, verify, cert, proxies)[0m
[0;32m    515[0m     [38;5;28;01mif[39;00m [38;5;28misinstance[39m(e[38;5;241m.[39mreason, _SSLError):
[0;32m    516[0m         [38;5;66;03m# This branch is for urllib3 v1.22 and later.[39;00m
[0;32m    517[0m         [38;5;28;01mraise[39;00m SSLError(e, request[38;5;241m=[39mrequest)
[1;32m--> 519[0m     [38;5;28;01mraise[39;00m [38;5;167;01mConnectionError[39;00m(e, request[38;5;241m=[39mrequest)
[0;32m    521[0m [38;5;28;01mexcept[39;00m ClosedPoolError [38;5;28;01mas[39;00m e:
[0;32m    522[0m     [38;5;28;01mraise[39;00m [38;5;167;01mConnectionError[39;00m(e, request[38;5;241m=[39mrequest)

[1;31mConnectionError[0m: HTTPConnectionPool(host='0.0.0.0', port=8000): Max retries exceeded with url: /graphql (Caused by NewConnectionError('<urllib3.connection.HTTPConnection object at 0x0000021E9671A350>: Failed to establish a new connection: [WinError 10049] The requested address is not valid in its context'))

