Traceback (most recent call last):
  File "C:\Users\Miguel\AppData\Local\Programs\Python\Python310\lib\site-packages\jupyter_cache\executors\utils.py", line 58, in single_nb_execution
    executenb(
  File "C:\Users\Miguel\AppData\Local\Programs\Python\Python310\lib\site-packages\nbclient\client.py", line 1314, in execute
    return NotebookClient(nb=nb, resources=resources, km=km, **kwargs).execute()
  File "C:\Users\Miguel\AppData\Local\Programs\Python\Python310\lib\site-packages\jupyter_core\utils\__init__.py", line 165, in wrapped
    return loop.run_until_complete(inner)
  File "C:\Users\Miguel\AppData\Local\Programs\Python\Python310\lib\asyncio\base_events.py", line 646, in run_until_complete
    return future.result()
  File "C:\Users\Miguel\AppData\Local\Programs\Python\Python310\lib\site-packages\nbclient\client.py", line 709, in async_execute
    await self.async_execute_cell(
  File "C:\Users\Miguel\AppData\Local\Programs\Python\Python310\lib\site-packages\nbclient\client.py", line 1062, in async_execute_cell
    await self._check_raise_for_error(cell, cell_index, exec_reply)
  File "C:\Users\Miguel\AppData\Local\Programs\Python\Python310\lib\site-packages\nbclient\client.py", line 918, in _check_raise_for_error
    raise CellExecutionError.from_cell_and_msg(cell, exec_reply_content)
nbclient.exceptions.CellExecutionError: An error occurred while executing the following cell:
------------------
data = data.pivot_table(index = "date", columns="catalog_id", values = "price", agg = "median")
data.head(10)
------------------


[1;31m---------------------------------------------------------------------------[0m
[1;31mNameError[0m                                 Traceback (most recent call last)
Cell [1;32mIn[2], line 1[0m
[1;32m----> 1[0m data [38;5;241m=[39m [43mdata[49m[38;5;241m.[39mpivot_table(index [38;5;241m=[39m [38;5;124m"[39m[38;5;124mdate[39m[38;5;124m"[39m, columns[38;5;241m=[39m[38;5;124m"[39m[38;5;124mcatalog_id[39m[38;5;124m"[39m, values [38;5;241m=[39m [38;5;124m"[39m[38;5;124mprice[39m[38;5;124m"[39m, agg [38;5;241m=[39m [38;5;124m"[39m[38;5;124mmedian[39m[38;5;124m"[39m)
[0;32m      2[0m data[38;5;241m.[39mhead([38;5;241m10[39m)

[1;31mNameError[0m: name 'data' is not defined

