Traceback (most recent call last):
  File "C:\Users\Miguel\AppData\Local\Programs\Python\Python310\lib\site-packages\jupyter_cache\executors\utils.py", line 58, in single_nb_execution
    executenb(
  File "C:\Users\Miguel\AppData\Local\Programs\Python\Python310\lib\site-packages\nbclient\client.py", line 1314, in execute
    return NotebookClient(nb=nb, resources=resources, km=km, **kwargs).execute()
  File "C:\Users\Miguel\AppData\Local\Programs\Python\Python310\lib\site-packages\jupyter_core\utils\__init__.py", line 165, in wrapped
    return loop.run_until_complete(inner)
  File "C:\Users\Miguel\AppData\Local\Programs\Python\Python310\lib\asyncio\base_events.py", line 646, in run_until_complete
    return future.result()
  File "C:\Users\Miguel\AppData\Local\Programs\Python\Python310\lib\site-packages\nbclient\client.py", line 709, in async_execute
    await self.async_execute_cell(
  File "C:\Users\Miguel\AppData\Local\Programs\Python\Python310\lib\site-packages\nbclient\client.py", line 1062, in async_execute_cell
    await self._check_raise_for_error(cell, cell_index, exec_reply)
  File "C:\Users\Miguel\AppData\Local\Programs\Python\Python310\lib\site-packages\nbclient\client.py", line 918, in _check_raise_for_error
    raise CellExecutionError.from_cell_and_msg(cell, exec_reply_content)
nbclient.exceptions.CellExecutionError: An error occurred while executing the following cell:
------------------
def load_credentials(path = "aws_rds_credentials.json"):
     with open(path, 'r') as file:
          config = json.load(file)

     # set up credentials
     for key in config.keys():
          os.environ[key] = config[key]

     return

time_interval = 90 #days

load_credentials()

aws_rds_url = f"postgresql://{os.environ['user']}:{os.environ['password']}@{os.environ['host']}:{os.environ['port']}/{os.environ['database']}?sslmode=require"

engine = create_engine(aws_rds_url)
sql_query = f"""SELECT catalog_id, price_numeric, size_title, brand_title, country, color1, status
               FROM public.tracking_staging 
               WHERE date >= CURRENT_DATE - INTERVAL '{time_interval} days'
               LIMIT 30000
               """
data = pd.read_sql(sql_query, engine)
data.head(10)
------------------


[1;31m---------------------------------------------------------------------------[0m
[1;31mFileNotFoundError[0m                         Traceback (most recent call last)
Cell [1;32mIn[2], line 13[0m
[0;32m      9[0m      [38;5;28;01mreturn[39;00m
[0;32m     11[0m time_interval [38;5;241m=[39m [38;5;241m90[39m [38;5;66;03m#days[39;00m
[1;32m---> 13[0m [43mload_credentials[49m[43m([49m[43m)[49m
[0;32m     15[0m aws_rds_url [38;5;241m=[39m [38;5;124mf[39m[38;5;124m"[39m[38;5;124mpostgresql://[39m[38;5;132;01m{[39;00mos[38;5;241m.[39menviron[[38;5;124m'[39m[38;5;124muser[39m[38;5;124m'[39m][38;5;132;01m}[39;00m[38;5;124m:[39m[38;5;132;01m{[39;00mos[38;5;241m.[39menviron[[38;5;124m'[39m[38;5;124mpassword[39m[38;5;124m'[39m][38;5;132;01m}[39;00m[38;5;124m@[39m[38;5;132;01m{[39;00mos[38;5;241m.[39menviron[[38;5;124m'[39m[38;5;124mhost[39m[38;5;124m'[39m][38;5;132;01m}[39;00m[38;5;124m:[39m[38;5;132;01m{[39;00mos[38;5;241m.[39menviron[[38;5;124m'[39m[38;5;124mport[39m[38;5;124m'[39m][38;5;132;01m}[39;00m[38;5;124m/[39m[38;5;132;01m{[39;00mos[38;5;241m.[39menviron[[38;5;124m'[39m[38;5;124mdatabase[39m[38;5;124m'[39m][38;5;132;01m}[39;00m[38;5;124m?sslmode=require[39m[38;5;124m"[39m
[0;32m     17[0m engine [38;5;241m=[39m create_engine(aws_rds_url)

Cell [1;32mIn[2], line 2[0m, in [0;36mload_credentials[1;34m(path)[0m
[0;32m      1[0m [38;5;28;01mdef[39;00m [38;5;21mload_credentials[39m(path [38;5;241m=[39m [38;5;124m"[39m[38;5;124maws_rds_credentials.json[39m[38;5;124m"[39m):
[1;32m----> 2[0m      [38;5;28;01mwith[39;00m [38;5;28;43mopen[39;49m[43m([49m[43mpath[49m[43m,[49m[43m [49m[38;5;124;43m'[39;49m[38;5;124;43mr[39;49m[38;5;124;43m'[39;49m[43m)[49m [38;5;28;01mas[39;00m file:
[0;32m      3[0m           config [38;5;241m=[39m json[38;5;241m.[39mload(file)
[0;32m      5[0m      [38;5;66;03m# set up credentials[39;00m

File [1;32m~\AppData\Local\Programs\Python\Python310\lib\site-packages\IPython\core\interactiveshell.py:284[0m, in [0;36m_modified_open[1;34m(file, *args, **kwargs)[0m
[0;32m    277[0m [38;5;28;01mif[39;00m file [38;5;129;01min[39;00m {[38;5;241m0[39m, [38;5;241m1[39m, [38;5;241m2[39m}:
[0;32m    278[0m     [38;5;28;01mraise[39;00m [38;5;167;01mValueError[39;00m(
[0;32m    279[0m         [38;5;124mf[39m[38;5;124m"[39m[38;5;124mIPython won[39m[38;5;124m'[39m[38;5;124mt let you open fd=[39m[38;5;132;01m{[39;00mfile[38;5;132;01m}[39;00m[38;5;124m by default [39m[38;5;124m"[39m
[0;32m    280[0m         [38;5;124m"[39m[38;5;124mas it is likely to crash IPython. If you know what you are doing, [39m[38;5;124m"[39m
[0;32m    281[0m         [38;5;124m"[39m[38;5;124myou can use builtins[39m[38;5;124m'[39m[38;5;124m open.[39m[38;5;124m"[39m
[0;32m    282[0m     )
[1;32m--> 284[0m [38;5;28;01mreturn[39;00m io_open(file, [38;5;241m*[39margs, [38;5;241m*[39m[38;5;241m*[39mkwargs)

[1;31mFileNotFoundError[0m: [Errno 2] No such file or directory: 'aws_rds_credentials.json'

