Traceback (most recent call last):
  File "C:\Users\Miguel\AppData\Local\Programs\Python\Python310\lib\site-packages\jupyter_cache\executors\utils.py", line 58, in single_nb_execution
    executenb(
  File "C:\Users\Miguel\AppData\Local\Programs\Python\Python310\lib\site-packages\nbclient\client.py", line 1314, in execute
    return NotebookClient(nb=nb, resources=resources, km=km, **kwargs).execute()
  File "C:\Users\Miguel\AppData\Local\Programs\Python\Python310\lib\site-packages\jupyter_core\utils\__init__.py", line 165, in wrapped
    return loop.run_until_complete(inner)
  File "C:\Users\Miguel\AppData\Local\Programs\Python\Python310\lib\asyncio\base_events.py", line 646, in run_until_complete
    return future.result()
  File "C:\Users\Miguel\AppData\Local\Programs\Python\Python310\lib\site-packages\nbclient\client.py", line 709, in async_execute
    await self.async_execute_cell(
  File "C:\Users\Miguel\AppData\Local\Programs\Python\Python310\lib\site-packages\nbclient\client.py", line 1062, in async_execute_cell
    await self._check_raise_for_error(cell, cell_index, exec_reply)
  File "C:\Users\Miguel\AppData\Local\Programs\Python\Python310\lib\site-packages\nbclient\client.py", line 918, in _check_raise_for_error
    raise CellExecutionError.from_cell_and_msg(cell, exec_reply_content)
nbclient.exceptions.CellExecutionError: An error occurred while executing the following cell:
------------------
from sklearn.linear_model import LinearRegression

reg = LinearRegression().fit(portfolio.drop(["Sharpe", "Revenue", "Volatility"], 
                            axis = 1), 
                            portfolio["Sharpe"])
coefficients = reg.coef_
top_5_indices = coefficients.argsort()[-5:][::-1]

# Get the corresponding labels
top_5_labels = portfolio.columns[top_5_indices]
for coef, label in zip(coefficients[top_5_indices], top_5_labels):
    print(f"{label}: {coef}")
------------------


[1;31m---------------------------------------------------------------------------[0m
[1;31mNameError[0m                                 Traceback (most recent call last)
Cell [1;32mIn[1], line 3[0m
[0;32m      1[0m [38;5;28;01mfrom[39;00m [38;5;21;01msklearn[39;00m[38;5;21;01m.[39;00m[38;5;21;01mlinear_model[39;00m [38;5;28;01mimport[39;00m LinearRegression
[1;32m----> 3[0m reg [38;5;241m=[39m LinearRegression()[38;5;241m.[39mfit([43mportfolio[49m[38;5;241m.[39mdrop([[38;5;124m"[39m[38;5;124mSharpe[39m[38;5;124m"[39m, [38;5;124m"[39m[38;5;124mRevenue[39m[38;5;124m"[39m, [38;5;124m"[39m[38;5;124mVolatility[39m[38;5;124m"[39m], 
[0;32m      4[0m                             axis [38;5;241m=[39m [38;5;241m1[39m), 
[0;32m      5[0m                             portfolio[[38;5;124m"[39m[38;5;124mSharpe[39m[38;5;124m"[39m])
[0;32m      6[0m coefficients [38;5;241m=[39m reg[38;5;241m.[39mcoef_
[0;32m      7[0m top_5_indices [38;5;241m=[39m coefficients[38;5;241m.[39margsort()[[38;5;241m-[39m[38;5;241m5[39m:][::[38;5;241m-[39m[38;5;241m1[39m]

[1;31mNameError[0m: name 'portfolio' is not defined

